<?xml version="1.0"?>
<robot name="bronchoscope">

  <link name="world"/>
  <joint name="world_fixed" type="fixed">
    <parent link="world"/>
    <child link="rail_link"/>
    <origin xyz="-0.1 0 0.485" rpy="0 0 0"/>
  </joint>

  <link name="rail_link">
    <inertial><mass value="1.0"/><inertia ixx="0.1" ixy="0" ixz="0" iyy="0.1" iyz="0" izz="0.1"/></inertial>
  </link>

  <joint name="insertion_joint" type="prismatic">
    <parent link="rail_link"/>
    <child link="base_link"/>
    <origin xyz="0 0 0" rpy="0 0 0"/>
    <axis xyz="1 0 0"/>
    <limit lower="-0.5" upper="1.5" effort="100.0" velocity="0.5"/>
  </joint>

  <link name="base_link">
    <visual>
      <origin xyz="-0.15 0 0" rpy="0 1.5708 0"/>
      <geometry><cylinder radius="0.015" length="0.3"/></geometry>
      <material name="gray"><color rgba="0.7 0.7 0.7 1.0"/></material>
    </visual>
    <collision>
      <origin xyz="-0.15 0 0" rpy="0 1.5708 0"/>
      <geometry><cylinder radius="0.015" length="0.3"/></geometry>
    </collision>
    <inertial><mass value="1.0"/><inertia ixx="0.01" ixy="0" ixz="0" iyy="0.01" iyz="0" izz="0.01"/></inertial>
  </link>
  <gazebo reference="base_link"><material>Gazebo/Grey</material><mu1>0.0</mu1><mu2>0.0</mu2></gazebo>

  <joint name="proximal_joint" type="revolute">
    <parent link="base_link"/>
    <child link="mid_link1"/>
    <origin xyz="0 0 0" rpy="0 0 0"/> 
    <axis xyz="0 0 1"/> 
    <limit lower="-0.6" upper="0.6" effort="100.0" velocity="1.0"/>
  </joint>

  <link name="mid_link1">
    <visual>
      <origin xyz="0.1 0 0" rpy="0 1.5708 0"/>
      <geometry><cylinder radius="0.014" length="0.2"/></geometry>
      <material name="dark_gray"><color rgba="0.5 0.5 0.5 1.0"/></material>
    </visual>
    <collision>
      <origin xyz="0.1 0 0" rpy="0 1.5708 0"/>
      <geometry><cylinder radius="0.014" length="0.2"/></geometry>
    </collision>
    <inertial><mass value="1.0"/><inertia ixx="0.01" ixy="0" ixz="0" iyy="0.01" iyz="0" izz="0.01"/></inertial>
  </link>
  <gazebo reference="mid_link1"><material>Gazebo/DarkGrey</material><mu1>0.0</mu1><mu2>0.0</mu2></gazebo>

  <joint name="mid_joint" type="revolute">
    <parent link="mid_link1"/>
    <child link="mid_link2"/>
    <origin xyz="0.2 0 0" rpy="0 0 0"/> 
    <axis xyz="0 0 1"/> 
    <limit lower="-1.0" upper="1.0" effort="100.0" velocity="1.0"/>
  </joint>

  <link name="mid_link2">
    <visual>
      <origin xyz="0.075 0 0" rpy="0 1.5708 0"/>
      <geometry><cylinder radius="0.013" length="0.15"/></geometry>
      <material name="gray"><color rgba="0.6 0.6 0.6 1.0"/></material>
    </visual>
    <collision>
      <origin xyz="0.075 0 0" rpy="0 1.5708 0"/>
      <geometry><cylinder radius="0.013" length="0.15"/></geometry>
    </collision>
    <inertial><mass value="1.0"/><inertia ixx="0.01" ixy="0" ixz="0" iyy="0.01" iyz="0" izz="0.01"/></inertial>
  </link>
  <gazebo reference="mid_link2"><material>Gazebo/Grey</material><mu1>0.0</mu1><mu2>0.0</mu2></gazebo>

  <joint name="distal_joint" type="revolute">
    <parent link="mid_link2"/>
    <child link="distal_tip"/>
    <origin xyz="0.15 0 0" rpy="0 0 0"/> 
    <axis xyz="0 0 1"/> 
    <limit lower="-1.57" upper="1.57" effort="100.0" velocity="1.0"/>
  </joint>

  <link name="distal_tip">
    <visual>
      <origin xyz="0.05 0 0" rpy="0 1.5708 0"/>
      <geometry><cylinder radius="0.012" length="0.1"/></geometry>
      <material name="black"><color rgba="0.1 0.1 0.1 1.0"/></material>
    </visual>
    <collision>
      <origin xyz="0.05 0 0" rpy="0 1.5708 0"/>
      <geometry><cylinder radius="0.012" length="0.1"/></geometry>
    </collision>
    <collision>
      <origin xyz="0.1 0 0" rpy="0 0 0"/>
      <geometry><sphere radius="0.012"/></geometry>
    </collision>
    <inertial><mass value="1.0"/><inertia ixx="0.01" ixy="0" ixz="0" iyy="0.01" iyz="0" izz="0.01"/></inertial>
  </link>
  <gazebo reference="distal_tip">
    <material>Gazebo/Black</material>
    <mu1>0.0</mu1><mu2>0.0</mu2>
    <sensor name="cmos_camera" type="camera">
      <pose>0.1 0 0 0 0 0</pose> 
      <always_on>true</always_on>
      <update_rate>30.0</update_rate>
      <camera>
        <horizontal_fov>1.047</horizontal_fov>
        <image><width>640</width><height>480</height><format>R8G8B8</format></image>
        <clip><near>0.01</near><far>10.0</far></clip>
      </camera>
    </sensor>
    <light name="cold_led" type="spot">
      <pose>0.1 0 0 0 0 0</pose> 
      <direction>1 0 0</direction>
      <attenuation><range>2.0</range><linear>0.05</linear><constant>0.1</constant><quadratic>0.001</quadratic></attenuation>
      <diffuse>0.9 0.9 1.0 1</diffuse>
      <specular>0.1 0.1 0.1 1</specular>
      <spot><inner_angle>0.5</inner_angle><outer_angle>1.2</outer_angle><falloff>1.0</falloff></spot>
      <cast_shadows>true</cast_shadows>
    </light>
  </gazebo>

  <ros2_control name="GazeboSimSystem" type="system">
    <hardware><plugin>gz_ros2_control/GazeboSimSystem</plugin></hardware>
    <joint name="insertion_joint">
      <command_interface name="position"><param name="min">-0.5</param><param name="max">1.5</param></command_interface>
      <state_interface name="position"/>
    </joint>
    <joint name="proximal_joint">
      <command_interface name="position"><param name="min">-0.6</param><param name="max">0.6</param></command_interface>
      <state_interface name="position"/>
    </joint>
    <joint name="mid_joint">
      <command_interface name="position"><param name="min">-1.0</param><param name="max">1.0</param></command_interface>
      <state_interface name="position"/>
    </joint>
    <joint name="distal_joint">
      <command_interface name="position"><param name="min">-1.57</param><param name="max">1.57</param></command_interface>
      <state_interface name="position"/>
    </joint>
  </ros2_control>

  <gazebo>
    <plugin filename="gz_ros2_control-system" name="gz_ros2_control::GazeboSimROS2ControlPlugin">
      <parameters>$(find smart_endoscope)/config/controllers.yaml</parameters>
    </plugin>
  </gazebo>
</robot>
